2021-03-15 17:38:15,631 ERROR: Exception on /auth/confirm [GET] [in /Users/weiqidu/project/website_new/venv/lib/python3.8/site-packages/flask/app.py:1891]
Traceback (most recent call last):
  File "/Users/weiqidu/project/website_new/venv/lib/python3.8/site-packages/flask/app.py", line 2447, in wsgi_app
    response = self.full_dispatch_request()
  File "/Users/weiqidu/project/website_new/venv/lib/python3.8/site-packages/flask/app.py", line 1952, in full_dispatch_request
    rv = self.handle_user_exception(e)
  File "/Users/weiqidu/project/website_new/venv/lib/python3.8/site-packages/flask/app.py", line 1821, in handle_user_exception
    reraise(exc_type, exc_value, tb)
  File "/Users/weiqidu/project/website_new/venv/lib/python3.8/site-packages/flask/_compat.py", line 39, in reraise
    raise value
  File "/Users/weiqidu/project/website_new/venv/lib/python3.8/site-packages/flask/app.py", line 1950, in full_dispatch_request
    rv = self.dispatch_request()
  File "/Users/weiqidu/project/website_new/venv/lib/python3.8/site-packages/flask/app.py", line 1936, in dispatch_request
    return self.view_functions[rule.endpoint](**req.view_args)
  File "/Users/weiqidu/project/website_new/venv/lib/python3.8/site-packages/flask_login/utils.py", line 272, in decorated_view
    return func(*args, **kwargs)
  File "/Users/weiqidu/project/website_new/app/auth/routes.py", line 81, in resend_confirmation
    send_confirm_email(current_user.email, '激活你的账户', 'auth/email/confirm', user=current_user, token=token)
TypeError: send_confirm_email() got multiple values for argument 'user'
2021-03-15 17:38:43,575 ERROR: Exception on /auth/confirm [GET] [in /Users/weiqidu/project/website_new/venv/lib/python3.8/site-packages/flask/app.py:1891]
Traceback (most recent call last):
  File "/Users/weiqidu/project/website_new/venv/lib/python3.8/site-packages/flask/app.py", line 2447, in wsgi_app
    response = self.full_dispatch_request()
  File "/Users/weiqidu/project/website_new/venv/lib/python3.8/site-packages/flask/app.py", line 1952, in full_dispatch_request
    rv = self.handle_user_exception(e)
  File "/Users/weiqidu/project/website_new/venv/lib/python3.8/site-packages/flask/app.py", line 1821, in handle_user_exception
    reraise(exc_type, exc_value, tb)
  File "/Users/weiqidu/project/website_new/venv/lib/python3.8/site-packages/flask/_compat.py", line 39, in reraise
    raise value
  File "/Users/weiqidu/project/website_new/venv/lib/python3.8/site-packages/flask/app.py", line 1950, in full_dispatch_request
    rv = self.dispatch_request()
  File "/Users/weiqidu/project/website_new/venv/lib/python3.8/site-packages/flask/app.py", line 1936, in dispatch_request
    return self.view_functions[rule.endpoint](**req.view_args)
  File "/Users/weiqidu/project/website_new/venv/lib/python3.8/site-packages/flask_login/utils.py", line 272, in decorated_view
    return func(*args, **kwargs)
  File "/Users/weiqidu/project/website_new/app/auth/routes.py", line 81, in resend_confirmation
    send_confirm_email(user)
TypeError: send_confirm_email() got multiple values for argument 'user'
2021-03-15 17:39:01,576 INFO: Microblog startup [in /Users/weiqidu/project/website_new/app/__init__.py:92]
2021-03-15 17:39:03,831 ERROR: Exception on /auth/confirm [GET] [in /Users/weiqidu/project/website_new/venv/lib/python3.8/site-packages/flask/app.py:1891]
Traceback (most recent call last):
  File "/Users/weiqidu/project/website_new/venv/lib/python3.8/site-packages/flask/app.py", line 2447, in wsgi_app
    response = self.full_dispatch_request()
  File "/Users/weiqidu/project/website_new/venv/lib/python3.8/site-packages/flask/app.py", line 1952, in full_dispatch_request
    rv = self.handle_user_exception(e)
  File "/Users/weiqidu/project/website_new/venv/lib/python3.8/site-packages/flask/app.py", line 1821, in handle_user_exception
    reraise(exc_type, exc_value, tb)
  File "/Users/weiqidu/project/website_new/venv/lib/python3.8/site-packages/flask/_compat.py", line 39, in reraise
    raise value
  File "/Users/weiqidu/project/website_new/venv/lib/python3.8/site-packages/flask/app.py", line 1950, in full_dispatch_request
    rv = self.dispatch_request()
  File "/Users/weiqidu/project/website_new/venv/lib/python3.8/site-packages/flask/app.py", line 1936, in dispatch_request
    return self.view_functions[rule.endpoint](**req.view_args)
  File "/Users/weiqidu/project/website_new/venv/lib/python3.8/site-packages/flask_login/utils.py", line 272, in decorated_view
    return func(*args, **kwargs)
  File "/Users/weiqidu/project/website_new/app/auth/routes.py", line 81, in resend_confirmation
    send_confirm_email(user)
NameError: name 'user' is not defined
2021-03-15 17:40:16,636 INFO: Microblog startup [in /Users/weiqidu/project/website_new/app/__init__.py:92]
2021-03-15 17:40:21,476 ERROR: Exception on /auth/confirm [GET] [in /Users/weiqidu/project/website_new/venv/lib/python3.8/site-packages/flask/app.py:1891]
Traceback (most recent call last):
  File "/Users/weiqidu/project/website_new/venv/lib/python3.8/site-packages/flask/app.py", line 2447, in wsgi_app
    response = self.full_dispatch_request()
  File "/Users/weiqidu/project/website_new/venv/lib/python3.8/site-packages/flask/app.py", line 1952, in full_dispatch_request
    rv = self.handle_user_exception(e)
  File "/Users/weiqidu/project/website_new/venv/lib/python3.8/site-packages/flask/app.py", line 1821, in handle_user_exception
    reraise(exc_type, exc_value, tb)
  File "/Users/weiqidu/project/website_new/venv/lib/python3.8/site-packages/flask/_compat.py", line 39, in reraise
    raise value
  File "/Users/weiqidu/project/website_new/venv/lib/python3.8/site-packages/flask/app.py", line 1950, in full_dispatch_request
    rv = self.dispatch_request()
  File "/Users/weiqidu/project/website_new/venv/lib/python3.8/site-packages/flask/app.py", line 1936, in dispatch_request
    return self.view_functions[rule.endpoint](**req.view_args)
  File "/Users/weiqidu/project/website_new/venv/lib/python3.8/site-packages/flask_login/utils.py", line 272, in decorated_view
    return func(*args, **kwargs)
  File "/Users/weiqidu/project/website_new/app/auth/routes.py", line 81, in resend_confirmation
    user = User.query.filter_by(email=form.email.data).first()
NameError: name 'form' is not defined
2021-03-15 17:43:20,044 INFO: Microblog startup [in /Users/weiqidu/project/website_new/app/__init__.py:92]
2021-03-15 17:43:23,653 ERROR: Exception on /auth/confirm [GET] [in /Users/weiqidu/project/website_new/venv/lib/python3.8/site-packages/flask/app.py:1891]
Traceback (most recent call last):
  File "/Users/weiqidu/project/website_new/venv/lib/python3.8/site-packages/flask/app.py", line 2447, in wsgi_app
    response = self.full_dispatch_request()
  File "/Users/weiqidu/project/website_new/venv/lib/python3.8/site-packages/flask/app.py", line 1952, in full_dispatch_request
    rv = self.handle_user_exception(e)
  File "/Users/weiqidu/project/website_new/venv/lib/python3.8/site-packages/flask/app.py", line 1821, in handle_user_exception
    reraise(exc_type, exc_value, tb)
  File "/Users/weiqidu/project/website_new/venv/lib/python3.8/site-packages/flask/_compat.py", line 39, in reraise
    raise value
  File "/Users/weiqidu/project/website_new/venv/lib/python3.8/site-packages/flask/app.py", line 1950, in full_dispatch_request
    rv = self.dispatch_request()
  File "/Users/weiqidu/project/website_new/venv/lib/python3.8/site-packages/flask/app.py", line 1936, in dispatch_request
    return self.view_functions[rule.endpoint](**req.view_args)
  File "/Users/weiqidu/project/website_new/venv/lib/python3.8/site-packages/flask_login/utils.py", line 272, in decorated_view
    return func(*args, **kwargs)
  File "/Users/weiqidu/project/website_new/app/auth/routes.py", line 81, in resend_confirmation
    user = User.query.filter_by(email=form.email.data).first()
NameError: name 'form' is not defined
2021-03-15 17:44:01,369 INFO: Microblog startup [in /Users/weiqidu/project/website_new/app/__init__.py:92]
2021-03-15 17:44:14,354 ERROR: Exception on /auth/confirm [GET] [in /Users/weiqidu/project/website_new/venv/lib/python3.8/site-packages/flask/app.py:1891]
Traceback (most recent call last):
  File "/Users/weiqidu/project/website_new/venv/lib/python3.8/site-packages/flask/app.py", line 2447, in wsgi_app
    response = self.full_dispatch_request()
  File "/Users/weiqidu/project/website_new/venv/lib/python3.8/site-packages/flask/app.py", line 1952, in full_dispatch_request
    rv = self.handle_user_exception(e)
  File "/Users/weiqidu/project/website_new/venv/lib/python3.8/site-packages/flask/app.py", line 1821, in handle_user_exception
    reraise(exc_type, exc_value, tb)
  File "/Users/weiqidu/project/website_new/venv/lib/python3.8/site-packages/flask/_compat.py", line 39, in reraise
    raise value
  File "/Users/weiqidu/project/website_new/venv/lib/python3.8/site-packages/flask/app.py", line 1950, in full_dispatch_request
    rv = self.dispatch_request()
  File "/Users/weiqidu/project/website_new/venv/lib/python3.8/site-packages/flask/app.py", line 1936, in dispatch_request
    return self.view_functions[rule.endpoint](**req.view_args)
  File "/Users/weiqidu/project/website_new/venv/lib/python3.8/site-packages/flask_login/utils.py", line 272, in decorated_view
    return func(*args, **kwargs)
  File "/Users/weiqidu/project/website_new/app/auth/routes.py", line 81, in resend_confirmation
    user = User.query.filter_by(email=form.email.data).first()
NameError: name 'form' is not defined
2021-03-15 17:45:33,216 INFO: Microblog startup [in /Users/weiqidu/project/website_new/app/__init__.py:92]
